<robot name="mobile_robot">

    <link name="base_footprint"/>
    
    <link name="base">
        <visual name="">
            <origin xyz="0.0 0.0 0.0" rpy="0.0 0.0 0.0"/>
            <geometry>
                <box size="0.4 0.4 0.1"/>
            </geometry>
            <material name="">
                <color rgba="1.0 0.0 0.0 1.0"/>
                <texture filename=""/>
            </material>
        </visual>
    </link>

    <joint name="joint_name" type="fixed">
        <parent link="base_footprint"/>
        <child link="base"/>
        <origin xyz="0.0 0.0 0.0" rpy="0.0 0.0 0.0"/>
    </joint>
    

    <link name="wheel_right">
        <visual name="">
            <origin xyz="0.0 0.0 0.0" rpy="0.0 0.0 0.0"/>
            <geometry>
                <cylinder radius="0.06" length="0.06"/>
            </geometry>
            <material name="">
                <color rgba="0.0 1.0 0.0 1.0"/>
                <texture filename=""/>
            </material>
        </visual>
    </link>

    <joint name="joint_wheel_right" type="continuous">
        <parent link="base"/>
        <child link="wheel_right"/>
        <axis xyz="0 0 -1"/>
        <origin xyz="0.2 -0.23 0" rpy="1.5707 0 0"/>
    </joint>
    
    
    <link name="wheel_left">
        <visual name="">
            <origin xyz="0.0 0.0 0.0" rpy="0.0 0.0 0.0"/>
            <geometry>
                <cylinder radius="0.06" length="0.06"/>
            </geometry>
            <material name="">
                <color rgba="0.0 1.0 0.0 1.0"/>
                <texture filename=""/>
            </material>
        </visual>
    </link>

    <joint name="joint_wheel_left" type="continuous">
        <parent link="base"/>
        <child link="wheel_left"/>
        <axis xyz="0 0 -1"/>
        <origin xyz="0.2 0.23 0" rpy="1.5707 0 0"/>
    </joint>

    <link name="wheel_mid">
        <visual name="">
            <origin xyz="0.0 0.0 0.0" rpy="0.0 0.0 0.0"/>
            <geometry>
                <cylinder radius="0.03" length="0.03"/>
            </geometry>
            <material name="">
                <color rgba="0.0 0.0 1.0 1.0"/>
                <texture filename=""/>
            </material>
        </visual>
    </link>

    <joint name="joint_wheel_mid" type="fixed">
        <parent link="base"/>
        <child link="wheel_mid"/>
        <origin xyz="-0.1 0.0 -0.05" rpy="0.0 0.0 0.0"/>
    </joint>
    



</robot>